REDACTED
REDACTED
stored_state.db
0.0.0.0
8000
True
REDACTED
password
 * Serving Flask app 'webserver'
 * Debug mode: on
WARNING: This is a development server. Do not use it in a production deployment. Use a production WSGI server instead.
 * Running on all addresses (0.0.0.0)
 * Running on http://127.0.0.1:8000
 * Running on http://192.168.1.133:8000
Press CTRL+C to quit
 * Restarting with stat
 * Debugger is active!
 * Debugger PIN: 129-569-286
192.168.1.1 - - [04/Feb/2023 19:04:18] "POST /set_status HTTP/1.1" 500 -
Traceback (most recent call last):
  File "/home/xethrus/paidProject/AvaliablilityProgram/webserver.py", line 117, in set_status
    retrieved_metadata = get_metadata_from_db()
  File "/home/xethrus/paidProject/AvaliablilityProgram/webserver.py", line 173, in get_metadata_from_db
    return metadata_return
UnboundLocalError: local variable 'metadata_return' referenced before assignment

During handling of the above exception, another exception occurred:

Traceback (most recent call last):
  File "/home/xethrus/.local/lib/python3.10/site-packages/flask/app.py", line 2548, in __call__
    return self.wsgi_app(environ, start_response)
  File "/home/xethrus/.local/lib/python3.10/site-packages/flask/app.py", line 2528, in wsgi_app
    response = self.handle_exception(e)
  File "/home/xethrus/.local/lib/python3.10/site-packages/flask/app.py", line 2525, in wsgi_app
    response = self.full_dispatch_request()
  File "/home/xethrus/.local/lib/python3.10/site-packages/flask/app.py", line 1822, in full_dispatch_request
    rv = self.handle_user_exception(e)
  File "/home/xethrus/.local/lib/python3.10/site-packages/flask/app.py", line 1820, in full_dispatch_request
    rv = self.dispatch_request()
  File "/home/xethrus/.local/lib/python3.10/site-packages/flask/app.py", line 1796, in dispatch_request
    return self.ensure_sync(self.view_functions[rule.endpoint])(**view_args)
  File "/home/xethrus/paidProject/AvaliablilityProgram/webserver.py", line 130, in set_status
    if(connection):
UnboundLocalError: local variable 'connection' referenced before assignment
192.168.1.1 - - [04/Feb/2023 19:04:18] "GET /get_status HTTP/1.1" 500 -
Traceback (most recent call last):
  File "/home/xethrus/.local/lib/python3.10/site-packages/flask/app.py", line 2548, in __call__
    return self.wsgi_app(environ, start_response)
  File "/home/xethrus/.local/lib/python3.10/site-packages/flask/app.py", line 2528, in wsgi_app
    response = self.handle_exception(e)
  File "/home/xethrus/.local/lib/python3.10/site-packages/flask/app.py", line 2525, in wsgi_app
    response = self.full_dispatch_request()
  File "/home/xethrus/.local/lib/python3.10/site-packages/flask/app.py", line 1822, in full_dispatch_request
    rv = self.handle_user_exception(e)
  File "/home/xethrus/.local/lib/python3.10/site-packages/flask/app.py", line 1820, in full_dispatch_request
    rv = self.dispatch_request()
  File "/home/xethrus/.local/lib/python3.10/site-packages/flask/app.py", line 1796, in dispatch_request
    return self.ensure_sync(self.view_functions[rule.endpoint])(**view_args)
  File "/home/xethrus/paidProject/AvaliablilityProgram/webserver.py", line 136, in get_status
    retrieved_metadata = get_metadata_from_db()
  File "/home/xethrus/paidProject/AvaliablilityProgram/webserver.py", line 173, in get_metadata_from_db
    return metadata_return
UnboundLocalError: local variable 'metadata_return' referenced before assignment
REDACTED
REDACTED
stored_state.db
0.0.0.0
8000
True
REDACTED
password
key accepted
failed to retrieve status Incorrect number of bindings supplied. The current statement uses 1, and there are 8 supplied.
failed to retrieve status Incorrect number of bindings supplied. The current statement uses 1, and there are 8 supplied.
